{
 "cells": [
  {
   "cell_type": "code",
   "execution_count": 9,
   "metadata": {},
   "outputs": [],
   "source": [
    "import numpy as np\n",
    "import matplotlib.pyplot as plt\n",
    "import seaborn as sns\n",
    "import tensorflow as tf\n",
    "import os"
   ]
  },
  {
   "cell_type": "code",
   "execution_count": 10,
   "metadata": {},
   "outputs": [
    {
     "data": {
      "text/plain": [
       "1179"
      ]
     },
     "execution_count": 10,
     "metadata": {},
     "output_type": "execute_result"
    }
   ],
   "source": [
    "import gc\n",
    "\n",
    "gc.collect()"
   ]
  },
  {
   "cell_type": "code",
   "execution_count": 3,
   "metadata": {},
   "outputs": [],
   "source": [
    "main_folder = '../'\n",
    "dataset_folder = main_folder + 'dataset/'\n",
    "logs_folder = main_folder + 'logs/'\n",
    "checkpoints_folder = main_folder + 'checkpoints/'"
   ]
  },
  {
   "cell_type": "code",
   "execution_count": 4,
   "metadata": {},
   "outputs": [],
   "source": [
    "X_train_canvas = np.load(dataset_folder + 'X_train_canvas.npy')\n",
    "coords = np.load(dataset_folder + 'coords.npy')\n",
    "y_train = np.load(dataset_folder + 'y_train.npy')\n",
    "X_test_canvas = np.load(dataset_folder + 'X_test_canvas.npy')\n",
    "coords_test = np.load(dataset_folder + 'coords_test.npy')\n",
    "y_test = np.load(dataset_folder + 'y_test.npy')"
   ]
  },
  {
   "cell_type": "code",
   "execution_count": 11,
   "metadata": {},
   "outputs": [],
   "source": [
    "train_data = tf.data.Dataset.from_tensor_slices((X_train_canvas, coords))\n",
    "test_data = tf.data.Dataset.from_tensor_slices((X_test_canvas, coords_test)) "
   ]
  },
  {
   "cell_type": "code",
   "execution_count": 12,
   "metadata": {},
   "outputs": [],
   "source": [
    "import mymodels\n",
    "\n",
    "model = mymodels.sect1()\n",
    "model.compile()"
   ]
  },
  {
   "cell_type": "code",
   "execution_count": 13,
   "metadata": {},
   "outputs": [
    {
     "ename": "ValueError",
     "evalue": "Exception encountered when calling Conv2D.call().\n\n\u001b[1mNegative dimension size caused by subtracting 3 from 1 for '{{node sequential_1_1/conv2d_2_1/convolution}} = Conv2D[T=DT_FLOAT, data_format=\"NHWC\", dilations=[1, 1, 1, 1], explicit_paddings=[], padding=\"VALID\", strides=[1, 1, 1, 1], use_cudnn_on_gpu=true](sequential_1_1/ExpandDims, sequential_1_1/conv2d_2_1/convolution/ReadVariableOp)' with input shapes: [128,128,1,1], [3,3,1,32].\u001b[0m\n\nArguments received by Conv2D.call():\n  • inputs=tf.Tensor(shape=(128, 128, 1, 1), dtype=float32)",
     "output_type": "error",
     "traceback": [
      "\u001b[1;31m---------------------------------------------------------------------------\u001b[0m",
      "\u001b[1;31mValueError\u001b[0m                                Traceback (most recent call last)",
      "Cell \u001b[1;32mIn[13], line 6\u001b[0m\n\u001b[0;32m      1\u001b[0m params \u001b[38;5;241m=\u001b[39m {\u001b[38;5;124m'\u001b[39m\u001b[38;5;124mepochs\u001b[39m\u001b[38;5;124m'\u001b[39m: \u001b[38;5;241m30\u001b[39m, \n\u001b[0;32m      2\u001b[0m           \u001b[38;5;124m'\u001b[39m\u001b[38;5;124mbatch_size\u001b[39m\u001b[38;5;124m'\u001b[39m: \u001b[38;5;241m1024\u001b[39m, \n\u001b[0;32m      3\u001b[0m           \u001b[38;5;124m'\u001b[39m\u001b[38;5;124mtensorboard\u001b[39m\u001b[38;5;124m'\u001b[39m: \u001b[38;5;28;01mTrue\u001b[39;00m, \n\u001b[0;32m      4\u001b[0m           \u001b[38;5;124m'\u001b[39m\u001b[38;5;124mcp_callback\u001b[39m\u001b[38;5;124m'\u001b[39m: \u001b[38;5;28;01mTrue\u001b[39;00m}\n\u001b[1;32m----> 6\u001b[0m run \u001b[38;5;241m=\u001b[39m model\u001b[38;5;241m.\u001b[39mtrain(train_data, test_data, params, logs_folder, checkpoints_folder)\n\u001b[0;32m      7\u001b[0m history_model \u001b[38;5;241m=\u001b[39m run\u001b[38;5;241m.\u001b[39mhistory\n\u001b[0;32m      8\u001b[0m \u001b[38;5;28mprint\u001b[39m(\u001b[38;5;124m\"\u001b[39m\u001b[38;5;124mThe history has the following data: \u001b[39m\u001b[38;5;124m\"\u001b[39m, history_model\u001b[38;5;241m.\u001b[39mkeys())\n",
      "File \u001b[1;32mh:\\aless\\Documents\\Python_Scripts\\Matur\\matura-private-main\\matura-private-1\\mymodels.py:96\u001b[0m, in \u001b[0;36msect1.train\u001b[1;34m(self, train_dataset, val_dataset, params, logs_folder, checkpoints_folder)\u001b[0m\n\u001b[0;32m     93\u001b[0m     callbacks\u001b[38;5;241m.\u001b[39mappend(cp_callback)\n\u001b[0;32m     95\u001b[0m \u001b[38;5;66;03m# Train the model\u001b[39;00m\n\u001b[1;32m---> 96\u001b[0m model_run \u001b[38;5;241m=\u001b[39m \u001b[38;5;28mself\u001b[39m\u001b[38;5;241m.\u001b[39mmodel\u001b[38;5;241m.\u001b[39mfit(\n\u001b[0;32m     97\u001b[0m     train_dataset,\n\u001b[0;32m     98\u001b[0m     epochs\u001b[38;5;241m=\u001b[39mparams[\u001b[38;5;124m'\u001b[39m\u001b[38;5;124mepochs\u001b[39m\u001b[38;5;124m'\u001b[39m],\n\u001b[0;32m     99\u001b[0m     validation_data\u001b[38;5;241m=\u001b[39mval_dataset,\n\u001b[0;32m    100\u001b[0m     callbacks\u001b[38;5;241m=\u001b[39mcallbacks,\n\u001b[0;32m    101\u001b[0m     verbose\u001b[38;5;241m=\u001b[39m\u001b[38;5;241m0\u001b[39m\n\u001b[0;32m    102\u001b[0m )\n\u001b[0;32m    103\u001b[0m \u001b[38;5;28;01mreturn\u001b[39;00m model_run\n",
      "File \u001b[1;32mc:\\Users\\aless\\anaconda3\\Lib\\site-packages\\keras\\src\\utils\\traceback_utils.py:122\u001b[0m, in \u001b[0;36mfilter_traceback.<locals>.error_handler\u001b[1;34m(*args, **kwargs)\u001b[0m\n\u001b[0;32m    119\u001b[0m     filtered_tb \u001b[38;5;241m=\u001b[39m _process_traceback_frames(e\u001b[38;5;241m.\u001b[39m__traceback__)\n\u001b[0;32m    120\u001b[0m     \u001b[38;5;66;03m# To get the full stack trace, call:\u001b[39;00m\n\u001b[0;32m    121\u001b[0m     \u001b[38;5;66;03m# `keras.config.disable_traceback_filtering()`\u001b[39;00m\n\u001b[1;32m--> 122\u001b[0m     \u001b[38;5;28;01mraise\u001b[39;00m e\u001b[38;5;241m.\u001b[39mwith_traceback(filtered_tb) \u001b[38;5;28;01mfrom\u001b[39;00m \u001b[38;5;28;01mNone\u001b[39;00m\n\u001b[0;32m    123\u001b[0m \u001b[38;5;28;01mfinally\u001b[39;00m:\n\u001b[0;32m    124\u001b[0m     \u001b[38;5;28;01mdel\u001b[39;00m filtered_tb\n",
      "File \u001b[1;32mc:\\Users\\aless\\anaconda3\\Lib\\site-packages\\keras\\src\\utils\\traceback_utils.py:122\u001b[0m, in \u001b[0;36mfilter_traceback.<locals>.error_handler\u001b[1;34m(*args, **kwargs)\u001b[0m\n\u001b[0;32m    119\u001b[0m     filtered_tb \u001b[38;5;241m=\u001b[39m _process_traceback_frames(e\u001b[38;5;241m.\u001b[39m__traceback__)\n\u001b[0;32m    120\u001b[0m     \u001b[38;5;66;03m# To get the full stack trace, call:\u001b[39;00m\n\u001b[0;32m    121\u001b[0m     \u001b[38;5;66;03m# `keras.config.disable_traceback_filtering()`\u001b[39;00m\n\u001b[1;32m--> 122\u001b[0m     \u001b[38;5;28;01mraise\u001b[39;00m e\u001b[38;5;241m.\u001b[39mwith_traceback(filtered_tb) \u001b[38;5;28;01mfrom\u001b[39;00m \u001b[38;5;28;01mNone\u001b[39;00m\n\u001b[0;32m    123\u001b[0m \u001b[38;5;28;01mfinally\u001b[39;00m:\n\u001b[0;32m    124\u001b[0m     \u001b[38;5;28;01mdel\u001b[39;00m filtered_tb\n",
      "\u001b[1;31mValueError\u001b[0m: Exception encountered when calling Conv2D.call().\n\n\u001b[1mNegative dimension size caused by subtracting 3 from 1 for '{{node sequential_1_1/conv2d_2_1/convolution}} = Conv2D[T=DT_FLOAT, data_format=\"NHWC\", dilations=[1, 1, 1, 1], explicit_paddings=[], padding=\"VALID\", strides=[1, 1, 1, 1], use_cudnn_on_gpu=true](sequential_1_1/ExpandDims, sequential_1_1/conv2d_2_1/convolution/ReadVariableOp)' with input shapes: [128,128,1,1], [3,3,1,32].\u001b[0m\n\nArguments received by Conv2D.call():\n  • inputs=tf.Tensor(shape=(128, 128, 1, 1), dtype=float32)"
     ]
    }
   ],
   "source": [
    "params = {'epochs': 30, \n",
    "          'batch_size': 1024, \n",
    "          'tensorboard': True, \n",
    "          'cp_callback': True}\n",
    "\n",
    "run = model.train(train_data, test_data, params, logs_folder, checkpoints_folder)\n",
    "history_model = run.history\n",
    "print(\"The history has the following data: \", history_model.keys())\n",
    "\n",
    "# Plotting the training and validation accuracy during the training\n",
    "sns.lineplot(\n",
    "    x=run.epoch, y=history_model[\"mean_absolute_error\"], color=\"blue\", label=\"Training set\"\n",
    ")\n",
    "sns.lineplot(\n",
    "    x=run.epoch,\n",
    "    y=history_model[\"val_mean_absolute_error\"],\n",
    "    color=\"red\",\n",
    "    label=\"Valdation set\",\n",
    ")\n",
    "plt.xlabel(\"epochs\")\n",
    "plt.ylabel(\"accuracy\")"
   ]
  },
  {
   "cell_type": "code",
   "execution_count": null,
   "metadata": {},
   "outputs": [],
   "source": [
    "cp_dir = checkpoints_folder + 'model_epoch_30.weights.h5'\n",
    "\n",
    "model.evaluate(X_test_2d, coords_test, cp_dir)"
   ]
  },
  {
   "cell_type": "code",
   "execution_count": null,
   "metadata": {},
   "outputs": [],
   "source": [
    "random_sample = np.random.randint(0, X_test_2d.shape[0])\n",
    "\n",
    "image = X_test_2d[random_sample]\n",
    "actual = coords_test[random_sample]\n",
    "prediction = model.predict(X_test_2d[random_sample].reshape(1, 128, 128, 1))\n",
    "\n",
    "plt.imshow(image, cmap='gray')\n",
    "#add dots to predicted values\n",
    "plt.scatter(prediction[0][0], prediction[0][1], color='red')\n",
    "plt.scatter(actual[0], actual[1], color='green')\n",
    "#add legend\n",
    "plt.legend(['Predicted', 'Actual'])\n",
    "plt.title(f\"Predicted: {prediction.round()}, Actual: {actual}\")\n",
    "plt.show()"
   ]
  }
 ],
 "metadata": {
  "kernelspec": {
   "display_name": "base",
   "language": "python",
   "name": "python3"
  },
  "language_info": {
   "codemirror_mode": {
    "name": "ipython",
    "version": 3
   },
   "file_extension": ".py",
   "mimetype": "text/x-python",
   "name": "python",
   "nbconvert_exporter": "python",
   "pygments_lexer": "ipython3",
   "version": "3.12.7"
  }
 },
 "nbformat": 4,
 "nbformat_minor": 2
}
